Workbook
Name Perf_Criterion_F.2.2.2_Performance_criteria: #REF!
Name Perf_Criterion_J.2.1_General: #REF!
Name Table_23: #REF!
Name Table_J.1: #REF!
Name Table_J.3: #REF!

Sheet Readme
A2: 1 | B2: This sheet is used to identify the field name list in following three Database
B3: TABLES_SAPMaxDB | C3: Database for Cadence (Old)
B4: TABLES_PostgreSQLDB | C4: New Database with "_l2u" suffix Table Name
B5: TABLES_AccessDB | C5: Database for Altium Designer in China (Old)
A6: 2 | B6: This workbook include following sheets (Which name by AccessDB Table Names)
C7: 01-Capacitors
C8: 02-Resistors
C9: 03-Varistors
C10: 04-Transistors
C11: 05-Diodes
C12: 06-ICs_digital
C13: 07-Memory
C14: 08-ICs_analog
C15: 09-Regulators
C16: 10-Converters
C17: 11-OP_Amps
C18: 12-Magnetics
... C31: 98-Shapes
A32: 3 | B32: In each sheet clarify the field name list for each Database and the mapping relationship.
B33: Row 1 | C33: Database Name (ref item 1)
B34: Row 2 | C34: Table Name of each Database
B35: Row 3 and others | C35: Field Name of each DB/Table
B37: Column D | C37: Check if the field name in the "TABLES_SAPMaxDB" and the "TABLES_PostgreSQLDB" are the same
C38: Result shown that the fied name are the same for above two DB, So the new "VIEW" tables for Cadence no need to change the field names.
B39: Column F | C39: Check if the field name in the "TABLES_AccessDB" and the "TABLES_PostgreSQLDB" are the same
C40: Result shown that mass different in between.
B41: Todo:
B42: a) | C42: Column B and Column E are the Tables to be created, field name mapping to the New PostgreDB is provided.
C43: Column B: for Cadence (CDS_CIS)
C44: Column E: for Altium Designer (AD)
A46: 4 | B46: In sheet "TableName_Mapping",field name mapping for three DB are listed.

Sheet TableName_Mapping
A1: Mapping
B2: New | C2: Altium CN(old) | D2: Cadence(CDS_CIS,old)
B3: TABLES_PostgreSQLDB | C3: TABLES_AccessDB | D3: TABLES_SAPMaxDB | E3: AD in used | G3: Old Table in Access | H3: in used in AD now | I3: Available in new DB?
B4: capacitors_l2u | C4: 01-Capacitors | D4: CAPACITORS | E4: =VLOOKUP(C4,G:H,2,FALSE) -> Y | G4: 01-Capacitors | H4: Y | I4: Y
B5: resistors_l2u | C5: 02-Resistors | D5: RESISTORS | E5: =VLOOKUP(C5,G:H,2,FALSE) -> Y | G5: 02-Resistors | H5: Y | I5: Y
B6: varistors_l2u | C6: 03-Varistors | D6: VARISTORS | E6: =VLOOKUP(C6,G:H,2,FALSE) -> Y | G6: 02-Resistors_Series | H6: N | I6: N
B7: transistors_l2u | C7: 04-Transistors | D7: TRANSISTORS | E7: =VLOOKUP(C7,G:H,2,FALSE) -> Y | G7: 03-Varistors | H7: Y | I7: Y
B8: diodes_l2u | C8: 05-Diodes | D8: DIODES | E8: =VLOOKUP(C8,G:H,2,FALSE) -> Y | G8: 04-Transistors | H8: Y | I8: Y
B9: ics_digital_l2u | C9: 06-ICs_digital | D9: ICS_DIGITAL | E9: =VLOOKUP(C9,G:H,2,FALSE) -> Y | G9: 05-Diodes | H9: Y | I9: Y
B10: memory_l2u | C10: 07-Memory | D10: MEMORY | E10: =VLOOKUP(C10,G:H,2,FALSE) -> Y | G10: 06-ICs_digital | H10: Y | I10: Y
B11: ics_analog_l2u | C11: 08-ICs_analog | D11: ICS_ANALOG | E11: =VLOOKUP(C11,G:H,2,FALSE) -> Y | G11: 07-Memory | H11: Y | I11: Y
B12: regulators_l2u | C12: 09-Regulators | D12: REGULATORS | E12: =VLOOKUP(C12,G:H,2,FALSE) -> Y | G12: 08-ICs_analog | H12: Y | I12: Y
B13: converters_l2u | C13: 10-Converters | D13: CONVERTERS | E13: =VLOOKUP(C13,G:H,2,FALSE) -> Y | G13: 09-Regulators | H13: Y | I13: Y
B14: op_amps_l2u | C14: 11-OP_Amps | D14: OP_AMPS | E14: =VLOOKUP(C14,G:H,2,FALSE) -> Y | G14: 10-Converters | H14: Y | I14: Y
B15: magnetics_l2u | C15: 12-Magnetics | D15: MAGNETICS | E15: =VLOOKUP(C15,G:H,2,FALSE) -> Y | G15: 11-OP_Amps | H15: Y | I15: Y
... B28: shapes_l2u | C28: 98-Shapes | D28: SHAPES | E28: =VLOOKUP(C28,G:H,2,FALSE) -> Y | G28: 24-Software | H28: N | I28: Y
B29: tmpprts_l2u | D29: TMPPRTS | F29: tmpprts stands for temporary parts. But as I look into the database, this database is not being used. The last entry in this database has been made in 2018 | G29: 90-Titleblock | H29: N | I29: Y
G30: 98-Shapes | H30: Y | I30: Y
G31: 99-MechPartsMAP | H31: N | I31: N

Sheet 01-Capacitors
A1: DB Name | B1: TABLES_SAPMaxDB | C1: TABLES_PostgreSQLDB | E1: TABLES_AccessDB
A2: Table Name | B2: CAPACITORS | C2: capacitors_l2u | D2: B=C? | E2: [01-Capacitors] | F2: C=E? | H2: No | I2: AccessDB left | J2: Comment
A3: Field List | B3: ad_alt_footprint | C3: ad_alt_footprint | D3: =IF(B3=C3,"Y","N") -> Y | E3: ad_alt_footprint | F3: =IF(C3=E3,"Y","N") -> Y | H3: 1 | I3: alt_symbols_cp | J3: Empty
B4: ad_footprint | C4: ad_footprint | D4: =IF(B4=C4,"Y","N") -> Y | E4: ad_footprint | F4: =IF(C4=E4,"Y","N") -> Y | H4: 2 | I4: bqr_partnum_mil | J4: Empty
B5: ad_symbol | C5: ad_symbol | D5: =IF(B5=C5,"Y","N") -> Y | E5: ad_symbol | F5: =IF(C5=E5,"Y","N") -> Y | H5: 3 | I5: bqr_partnum_sie | J5: Empty
B6: alt_symbols | C6: alt_symbols | D6: =IF(B6=C6,"Y","N") -> Y | E6: alt_symbols | F6: =IF(C6=E6,"Y","N") -> Y | H6: 4 | I6: class | J6: some with "DISCRETE" value
B7: annualconsumption | C7: annualconsumption | D7: =IF(B7=C7,"Y","N") -> Y | E7: annualconsumption | F7: =IF(C7=E7,"Y","N") -> Y | H7: 5 | I7: compmaterial | J7: Empty
B8: approvals_of_part | C8: approvals_of_part | D8: =IF(B8=C8,"Y","N") -> Y | E8: approvals of part | F8: =IF(C8=E8,"Y","N") -> N | H8: 6 | I8: comptype | J8: Empty
B9: approvals_required | C9: approvals_required | D9: =IF(B9=C9,"Y","N") -> Y | E9: approvals required | F9: =IF(C9=E9,"Y","N") -> N | H9: 7 | I9: further_information | J9: Empty
B10: capvoltage | C10: capvoltage | D10: =IF(B10=C10,"Y","N") -> Y | E10: capvoltage | F10: =IF(C10=E10,"Y","N") -> Y | H10: 8 | I10: mechmodell | J10: Empty
B11: datasheet_1 | C11: datasheet_1 | D11: =IF(B11=C11,"Y","N") -> Y | E11: datasheet 1 | F11: =IF(C11=E11,"Y","N") -> N | H11: 9 | I11: parthistory | J11: Empty
B12: datasheet_2 | C12: datasheet_2 | D12: =IF(B12=C12,"Y","N") -> Y | E12: datasheet 2 | F12: =IF(C12=E12,"Y","N") -> N | H12: 10 | I12: pcb_footprint_cp | J12: Empty
B13: datasheet_3 | C13: datasheet_3 | D13: =IF(B13=C13,"Y","N") -> Y | E13: datasheet 3 | F13: =IF(C13=E13,"Y","N") -> N | H13: 11 | I13: pspicetemp | J13: Empty
B14: datasheet_4 | C14: datasheet_4 | D14: =IF(B14=C14,"Y","N") -> Y | E14: datasheet 4 | F14: =IF(C14=E14,"Y","N") -> N | H14: 12 | I14: restrictedsubstances | J14: Empty
B15: datasheet_5 | C15: datasheet_5 | D15: =IF(B15=C15,"Y","N") -> Y | E15: datasheet 5 | F15: =IF(C15=E15,"Y","N") -> N | H15: 13 | I15: rohs_china | J15: Empty
... B24: free_comment | C24: free_comment | D24: =IF(B24=C24,"Y","N") -> Y | E24: free_comment | F24: =IF(C24=E24,"Y","N") -> Y | H24: 22 | I24: activepartsid | J24: Empty
B25: height | C25: height | D25: =IF(B25=C25,"Y","N") -> Y | E25: height | F25: =IF(C25=E25,"Y","N") -> Y
B26: id | C26: id | D26: =IF(B26=C26,"Y","N") -> Y | F26: =IF(C26=E26,"Y","N") -> N | G26: Should use "id" for new Table
B27: implementation | C27: implementation | D27: =IF(B27=C27,"Y","N") -> Y | E27: implementation | F27: =IF(C27=E27,"Y","N") -> Y
B28: in_approved_devices | C28: in_approved_devices | D28: =IF(B28=C28,"Y","N") -> Y | E28: in approved devices | F28: =IF(C28=E28,"Y","N") -> N
B29: manufact_1 | C29: manufact_1 | D29: =IF(B29=C29,"Y","N") -> Y | E29: manufact 1 | F29: =IF(C29=E29,"Y","N") -> N
B30: manufact_2 | C30: manufact_2 | D30: =IF(B30=C30,"Y","N") -> Y | E30: manufact 2 | F30: =IF(C30=E30,"Y","N") -> N
B31: manufact_3 | C31: manufact_3 | D31: =IF(B31=C31,"Y","N") -> Y | E31: manufact 3 | F31: =IF(C31=E31,"Y","N") -> N
B32: manufact_4 | C32: manufact_4 | D32: =IF(B32=C32,"Y","N") -> Y | E32: manufact 4 | F32: =IF(C32=E32,"Y","N") -> N
B33: manufact_5 | C33: manufact_5 | D33: =IF(B33=C33,"Y","N") -> Y | E33: manufact 5 | F33: =IF(C33=E33,"Y","N") -> N
B34: manufact_6 | C34: manufact_6 | D34: =IF(B34=C34,"Y","N") -> Y | E34: manufact 6 | F34: =IF(C34=E34,"Y","N") -> N
B35: manufact_7 | C35: manufact_7 | D35: =IF(B35=C35,"Y","N") -> Y | E35: manufact 7 | F35: =IF(C35=E35,"Y","N") -> N
B36: manufact_partnum_1 | C36: manufact_partnum_1 | D36: =IF(B36=C36,"Y","N") -> Y | E36: manufact partnum 1 | F36: =IF(C36=E36,"Y","N") -> N
B37: manufact_partnum_2 | C37: manufact_partnum_2 | D37: =IF(B37=C37,"Y","N") -> Y | E37: manufact partnum 2 | F37: =IF(C37=E37,"Y","N") -> N
B38: manufact_partnum_3 | C38: manufact_partnum_3 | D38: =IF(B38=C38,"Y","N") -> Y | E38: manufact partnum 3 | F38: =IF(C38=E38,"Y","N") -> N
... B71: value_1 | C71: value_1 | D71: =IF(B71=C71,"Y","N") -> Y | E71: value | F71: =IF(C71=E71,"Y","N") -> N

Sheet 02-Resistors
A1: DB Name | B1: TABLES_SAPMaxDB | C1: TABLES_PostgreSQLDB | E1: TABLES_AccessDB
A2: Table Name | B2: RESISTORS | C2: resistors_l2u | D2: B=C? | E2: [02-Resistors] | F2: C=E? | H2: No | I2: AccessDB left | J2: Comment
A3: Field List | B3: ad_alt_footprint | C3: ad_alt_footprint | D3: =IF(B3=C3,"Y","N") -> Y | E3: ad_alt_footprint | F3: =IF(C3=E3,"Y","N") -> Y | H3: 1 | I3: activepartsid | J3: =VLOOKUP(I3,'01-Capacitors'!I:J,2,FALSE) -> Empty
B4: ad_footprint | C4: ad_footprint | D4: =IF(B4=C4,"Y","N") -> Y | E4: ad_footprint | F4: =IF(C4=E4,"Y","N") -> Y | H4: 2 | I4: alt_symbols_cp | J4: =VLOOKUP(I4,'01-Capacitors'!I:J,2,FALSE) -> Empty
B5: ad_symbol | C5: ad_symbol | D5: =IF(B5=C5,"Y","N") -> Y | E5: ad_symbol | F5: =IF(C5=E5,"Y","N") -> Y | H5: 3 | I5: bqr_partnum_mil | J5: =VLOOKUP(I5,'01-Capacitors'!I:J,2,FALSE) -> Empty
B6: alt_symbols | C6: alt_symbols | D6: =IF(B6=C6,"Y","N") -> Y | E6: alt_symbols | F6: =IF(C6=E6,"Y","N") -> Y | H6: 4 | I6: bqr_partnum_sie | J6: =VLOOKUP(I6,'01-Capacitors'!I:J,2,FALSE) -> Empty
B7: annualconsumption | C7: annualconsumption | D7: =IF(B7=C7,"Y","N") -> Y | E7: annualconsumption | F7: =IF(C7=E7,"Y","N") -> Y | H7: 5 | I7: class | J7: =VLOOKUP(I7,'01-Capacitors'!I:J,2,FALSE) -> some with "DISCRETE" value
B8: approvals_of_part | C8: approvals_of_part | D8: =IF(B8=C8,"Y","N") -> Y | E8: approvals of part | F8: =IF(C8=E8,"Y","N") -> N | H8: 6 | I8: compmaterial | J8: =VLOOKUP(I8,'01-Capacitors'!I:J,2,FALSE) -> Empty
B9: approvals_required | C9: approvals_required | D9: =IF(B9=C9,"Y","N") -> Y | E9: approvals required | F9: =IF(C9=E9,"Y","N") -> N | H9: 7 | I9: comptype | J9: =VLOOKUP(I9,'01-Capacitors'!I:J,2,FALSE) -> Empty
B10: datasheet_1 | C10: datasheet_1 | D10: =IF(B10=C10,"Y","N") -> Y | E10: datasheet 1 | F10: =IF(C10=E10,"Y","N") -> N | H10: 8 | I10: further_information | J10: =VLOOKUP(I10,'01-Capacitors'!I:J,2,FALSE) -> Empty
B11: datasheet_2 | C11: datasheet_2 | D11: =IF(B11=C11,"Y","N") -> Y | E11: datasheet 2 | F11: =IF(C11=E11,"Y","N") -> N | H11: 9 | I11: mechmodell | J11: =VLOOKUP(I11,'01-Capacitors'!I:J,2,FALSE) -> Empty
B12: datasheet_3 | C12: datasheet_3 | D12: =IF(B12=C12,"Y","N") -> Y | E12: datasheet 3 | F12: =IF(C12=E12,"Y","N") -> N | H12: 10 | I12: parthistory | J12: =VLOOKUP(I12,'01-Capacitors'!I:J,2,FALSE) -> Empty
B13: datasheet_4 | C13: datasheet_4 | D13: =IF(B13=C13,"Y","N") -> Y | E13: datasheet 4 | F13: =IF(C13=E13,"Y","N") -> N | H13: 11 | I13: pspicetemp | J13: =VLOOKUP(I13,'01-Capacitors'!I:J,2,FALSE) -> Empty
B14: datasheet_5 | C14: datasheet_5 | D14: =IF(B14=C14,"Y","N") -> Y | E14: datasheet 5 | F14: =IF(C14=E14,"Y","N") -> N | H14: 12 | I14: pcb_footprint_cp | J14: =VLOOKUP(I14,'01-Capacitors'!I:J,2,FALSE) -> Empty
B15: datasheet_6 | C15: datasheet_6 | D15: =IF(B15=C15,"Y","N") -> Y | E15: datasheet 6 | F15: =IF(C15=E15,"Y","N") -> N | H15: 13 | I15: restrictedsubstances | J15: =VLOOKUP(I15,'01-Capacitors'!I:J,2,FALSE) -> Empty
... B22: height | C22: height | D22: =IF(B22=C22,"Y","N") -> Y | E22: height | F22: =IF(C22=E22,"Y","N") -> Y | H22: 20 | I22: soldertemperatur_wave | J22: =VLOOKUP(I22,'01-Capacitors'!I:J,2,FALSE) -> Empty
B23: id | C23: id | D23: =IF(B23=C23,"Y","N") -> Y | F23: =IF(C23=E23,"Y","N") -> N | G23: Should use "id" for new Table | H23: 21 | I23: thetajb | J23: =VLOOKUP(I23,'01-Capacitors'!I:J,2,FALSE) -> Empty
B24: implementation | C24: implementation | D24: =IF(B24=C24,"Y","N") -> Y | E24: implementation | F24: =IF(C24=E24,"Y","N") -> Y | H24: 22 | I24: thetajc | J24: =VLOOKUP(I24,'01-Capacitors'!I:J,2,FALSE) -> Empty
B25: in_approved_devices | C25: in_approved_devices | D25: =IF(B25=C25,"Y","N") -> Y | E25: in approved devices | F25: =IF(C25=E25,"Y","N") -> N
B26: manufact_1 | C26: manufact_1 | D26: =IF(B26=C26,"Y","N") -> Y | E26: manufact 1 | F26: =IF(C26=E26,"Y","N") -> N
B27: manufact_2 | C27: manufact_2 | D27: =IF(B27=C27,"Y","N") -> Y | E27: manufact 2 | F27: =IF(C27=E27,"Y","N") -> N
B28: manufact_3 | C28: manufact_3 | D28: =IF(B28=C28,"Y","N") -> Y | E28: manufact 3 | F28: =IF(C28=E28,"Y","N") -> N
B29: manufact_4 | C29: manufact_4 | D29: =IF(B29=C29,"Y","N") -> Y | E29: manufact 4 | F29: =IF(C29=E29,"Y","N") -> N
B30: manufact_5 | C30: manufact_5 | D30: =IF(B30=C30,"Y","N") -> Y | E30: manufact 5 | F30: =IF(C30=E30,"Y","N") -> N
B31: manufact_6 | C31: manufact_6 | D31: =IF(B31=C31,"Y","N") -> Y | E31: manufact 6 | F31: =IF(C31=E31,"Y","N") -> N
B32: manufact_7 | C32: manufact_7 | D32: =IF(B32=C32,"Y","N") -> Y | E32: manufact 7 | F32: =IF(C32=E32,"Y","N") -> N
B33: manufact_partnum_1 | C33: manufact_partnum_1 | D33: =IF(B33=C33,"Y","N") -> Y | E33: manufact partnum 1 | F33: =IF(C33=E33,"Y","N") -> N
B34: manufact_partnum_2 | C34: manufact_partnum_2 | D34: =IF(B34=C34,"Y","N") -> Y | E34: manufact partnum 2 | F34: =IF(C34=E34,"Y","N") -> N
B35: manufact_partnum_3 | C35: manufact_partnum_3 | D35: =IF(B35=C35,"Y","N") -> Y | E35: manufact partnum 3 | F35: =IF(C35=E35,"Y","N") -> N
B36: manufact_partnum_4 | C36: manufact_partnum_4 | D36: =IF(B36=C36,"Y","N") -> Y | E36: manufact partnum 4 | F36: =IF(C36=E36,"Y","N") -> N
... B70: value_1 | C70: value_1 | D70: =IF(B70=C70,"Y","N") -> Y | E70: value | F70: =IF(C70=E70,"Y","N") -> N

Sheet 03-Varistors
A1: DB Name | B1: TABLES_SAPMaxDB | C1: TABLES_PostgreSQLDB | E1: TABLES_AccessDB
A2: Table Name | B2: VARISTORS | C2: varistors_l2u | D2: B=C? | E2: [03-Varistors] | F2: C=E? | H2: No | I2: AccessDB left | J2: Comment
A3: Field List | B3: ad_alt_footprint | C3: ad_alt_footprint | D3: =IF(B3=C3,"Y","N") -> Y | E3: ad_alt_footprint | F3: =IF(C3=E3,"Y","N") -> Y | H3: 1 | I3: alt_symbols_cp | J3: =VLOOKUP(I3,'01-Capacitors'!I:J,2,FALSE) -> Empty
B4: ad_footprint | C4: ad_footprint | D4: =IF(B4=C4,"Y","N") -> Y | E4: ad_footprint | F4: =IF(C4=E4,"Y","N") -> Y | H4: 2 | I4: bqr_partnum_mil | J4: =VLOOKUP(I4,'01-Capacitors'!I:J,2,FALSE) -> Empty
B5: ad_symbol | C5: ad_symbol | D5: =IF(B5=C5,"Y","N") -> Y | E5: ad_symbol | F5: =IF(C5=E5,"Y","N") -> Y | H5: 3 | I5: bqr_partnum_sie | J5: =VLOOKUP(I5,'01-Capacitors'!I:J,2,FALSE) -> Empty
B6: alt_symbols | C6: alt_symbols | D6: =IF(B6=C6,"Y","N") -> Y | E6: alt_symbols | F6: =IF(C6=E6,"Y","N") -> Y | H6: 4 | I6: class | J6: =VLOOKUP(I6,'01-Capacitors'!I:J,2,FALSE) -> some with "DISCRETE" value
B7: annualconsumption | C7: annualconsumption | D7: =IF(B7=C7,"Y","N") -> Y | E7: annualconsumption | F7: =IF(C7=E7,"Y","N") -> Y | H7: 5 | I7: compmaterial | J7: =VLOOKUP(I7,'01-Capacitors'!I:J,2,FALSE) -> Empty
B8: approvals_of_part | C8: approvals_of_part | D8: =IF(B8=C8,"Y","N") -> Y | E8: approvals of part | F8: =IF(C8=E8,"Y","N") -> N | H8: 6 | I8: comptype | J8: =VLOOKUP(I8,'01-Capacitors'!I:J,2,FALSE) -> Empty
B9: approvals_required | C9: approvals_required | D9: =IF(B9=C9,"Y","N") -> Y | E9: approvals required | F9: =IF(C9=E9,"Y","N") -> N | H9: 7 | I9: further_information | J9: =VLOOKUP(I9,'01-Capacitors'!I:J,2,FALSE) -> Empty
B10: clampingvoltage | C10: clampingvoltage | D10: =IF(B10=C10,"Y","N") -> Y | E10: clampingvoltage | F10: =IF(C10=E10,"Y","N") -> Y | H10: 8 | I10: mechmodell | J10: =VLOOKUP(I10,'01-Capacitors'!I:J,2,FALSE) -> Empty
B11: datasheet_1 | C11: datasheet_1 | D11: =IF(B11=C11,"Y","N") -> Y | E11: datasheet 1 | F11: =IF(C11=E11,"Y","N") -> N | H11: 9 | I11: parthistory | J11: =VLOOKUP(I11,'01-Capacitors'!I:J,2,FALSE) -> Empty
B12: datasheet_2 | C12: datasheet_2 | D12: =IF(B12=C12,"Y","N") -> Y | E12: datasheet 2 | F12: =IF(C12=E12,"Y","N") -> N | H12: 10 | I12: pcb_footprint_cp | J12: =VLOOKUP(I12,'01-Capacitors'!I:J,2,FALSE) -> Empty
B13: datasheet_3 | C13: datasheet_3 | D13: =IF(B13=C13,"Y","N") -> Y | E13: datasheet 3 | F13: =IF(C13=E13,"Y","N") -> N | H13: 11 | I13: pspicetemp | J13: =VLOOKUP(I13,'01-Capacitors'!I:J,2,FALSE) -> Empty
B14: datasheet_4 | C14: datasheet_4 | D14: =IF(B14=C14,"Y","N") -> Y | E14: datasheet 4 | F14: =IF(C14=E14,"Y","N") -> N | H14: 12 | I14: restrictedsubstances | J14: =VLOOKUP(I14,'01-Capacitors'!I:J,2,FALSE) -> Empty
B15: datasheet_5 | C15: datasheet_5 | D15: =IF(B15=C15,"Y","N") -> Y | E15: datasheet 5 | F15: =IF(C15=E15,"Y","N") -> N | H15: 13 | I15: rohs_china | J15: =VLOOKUP(I15,'01-Capacitors'!I:J,2,FALSE) -> Empty
... B23: height | C23: height | D23: =IF(B23=C23,"Y","N") -> Y | E23: height | F23: =IF(C23=E23,"Y","N") -> Y | H23: 21 | I23: thetajc | J23: =VLOOKUP(I23,'01-Capacitors'!I:J,2,FALSE) -> Empty
B24: id | C24: id | D24: =IF(B24=C24,"Y","N") -> Y | F24: =IF(C24=E24,"Y","N") -> N | G24: Should use "id" for new Table | H24: 22 | I24: activepartsid | J24: =VLOOKUP(I24,'01-Capacitors'!I:J,2,FALSE) -> Empty
B25: implementation | C25: implementation | D25: =IF(B25=C25,"Y","N") -> Y | E25: implementation | F25: =IF(C25=E25,"Y","N") -> Y
B26: in_approved_devices | C26: in_approved_devices | D26: =IF(B26=C26,"Y","N") -> Y | E26: in approved devices | F26: =IF(C26=E26,"Y","N") -> N
B27: manufact_1 | C27: manufact_1 | D27: =IF(B27=C27,"Y","N") -> Y | E27: manufact 1 | F27: =IF(C27=E27,"Y","N") -> N
B28: manufact_2 | C28: manufact_2 | D28: =IF(B28=C28,"Y","N") -> Y | E28: manufact 2 | F28: =IF(C28=E28,"Y","N") -> N
B29: manufact_3 | C29: manufact_3 | D29: =IF(B29=C29,"Y","N") -> Y | E29: manufact 3 | F29: =IF(C29=E29,"Y","N") -> N
B30: manufact_4 | C30: manufact_4 | D30: =IF(B30=C30,"Y","N") -> Y | E30: manufact 4 | F30: =IF(C30=E30,"Y","N") -> N
B31: manufact_5 | C31: manufact_5 | D31: =IF(B31=C31,"Y","N") -> Y | E31: manufact 5 | F31: =IF(C31=E31,"Y","N") -> N
B32: manufact_6 | C32: manufact_6 | D32: =IF(B32=C32,"Y","N") -> Y | E32: manufact 6 | F32: =IF(C32=E32,"Y","N") -> N
B33: manufact_7 | C33: manufact_7 | D33: =IF(B33=C33,"Y","N") -> Y | E33: manufact 7 | F33: =IF(C33=E33,"Y","N") -> N
B34: manufact_partnum_1 | C34: manufact_partnum_1 | D34: =IF(B34=C34,"Y","N") -> Y | E34: manufact partnum 1 | F34: =IF(C34=E34,"Y","N") -> N
B35: manufact_partnum_2 | C35: manufact_partnum_2 | D35: =IF(B35=C35,"Y","N") -> Y | E35: manufact partnum 2 | F35: =IF(C35=E35,"Y","N") -> N
B36: manufact_partnum_3 | C36: manufact_partnum_3 | D36: =IF(B36=C36,"Y","N") -> Y | E36: manufact partnum 3 | F36: =IF(C36=E36,"Y","N") -> N
... B71: workingvolt | C71: workingvolt | D71: =IF(B71=C71,"Y","N") -> Y | E71: workingvolt | F71: =IF(C71=E71,"Y","N") -> Y

Sheet 04-Transistors
A1: DB Name | B1: TABLES_SAPMaxDB | C1: TABLES_PostgreSQLDB | E1: TABLES_AccessDB
A2: Table Name | B2: TRANSISTORS | C2: transistors_l2u | D2: B=C? | E2: [04-Transistors] | F2: C=E? | H2: No | I2: AccessDB left | J2: Comment
A3: Field List | B3: ad_alt_footprint | C3: ad_alt_footprint | D3: =IF(B3=C3,"Y","N") -> Y | E3: ad_alt_footprint | F3: =IF(C3=E3,"Y","N") -> Y | H3: 1 | I3: activepartsid | J3: =VLOOKUP(I3,'01-Capacitors'!I:J,2,FALSE) -> Empty
B4: ad_footprint | C4: ad_footprint | D4: =IF(B4=C4,"Y","N") -> Y | E4: ad_footprint | F4: =IF(C4=E4,"Y","N") -> Y | H4: 2 | I4: alt_symbols_cp | J4: =VLOOKUP(I4,'01-Capacitors'!I:J,2,FALSE) -> Empty
B5: ad_symbol | C5: ad_symbol | D5: =IF(B5=C5,"Y","N") -> Y | E5: ad_symbol | F5: =IF(C5=E5,"Y","N") -> Y | H5: 3 | I5: bqr_partnum_mil | J5: =VLOOKUP(I5,'01-Capacitors'!I:J,2,FALSE) -> Empty
B6: alt_symbols | C6: alt_symbols | D6: =IF(B6=C6,"Y","N") -> Y | E6: alt_symbols | F6: =IF(C6=E6,"Y","N") -> Y | H6: 4 | I6: bqr_partnum_sie | J6: =VLOOKUP(I6,'01-Capacitors'!I:J,2,FALSE) -> Empty
B7: annualconsumption | C7: annualconsumption | D7: =IF(B7=C7,"Y","N") -> Y | E7: annualconsumption | F7: =IF(C7=E7,"Y","N") -> Y | H7: 5 | I7: class | J7: =VLOOKUP(I7,'01-Capacitors'!I:J,2,FALSE) -> some with "DISCRETE" value
B8: approvals_of_part | C8: approvals_of_part | D8: =IF(B8=C8,"Y","N") -> Y | E8: approvals of part | F8: =IF(C8=E8,"Y","N") -> N | H8: 6 | I8: compmaterial | J8: =VLOOKUP(I8,'01-Capacitors'!I:J,2,FALSE) -> Empty
B9: approvals_required | C9: approvals_required | D9: =IF(B9=C9,"Y","N") -> Y | E9: approvals required | F9: =IF(C9=E9,"Y","N") -> N | H9: 7 | I9: comptype | J9: =VLOOKUP(I9,'01-Capacitors'!I:J,2,FALSE) -> Empty
B10: b_rdson | C10: b_rdson | D10: =IF(B10=C10,"Y","N") -> Y | E10: b / rdson | F10: =IF(C10=E10,"Y","N") -> N | G10: should use PostgreDB filed name | H10: 8 | I10: further_information | J10: =VLOOKUP(I10,'01-Capacitors'!I:J,2,FALSE) -> Empty
B11: datasheet_1 | C11: datasheet_1 | D11: =IF(B11=C11,"Y","N") -> Y | E11: datasheet 1 | F11: =IF(C11=E11,"Y","N") -> N | H11: 9 | I11: mechmodell | J11: =VLOOKUP(I11,'01-Capacitors'!I:J,2,FALSE) -> Empty
B12: datasheet_2 | C12: datasheet_2 | D12: =IF(B12=C12,"Y","N") -> Y | E12: datasheet 2 | F12: =IF(C12=E12,"Y","N") -> N | H12: 10 | I12: parthistory | J12: =VLOOKUP(I12,'01-Capacitors'!I:J,2,FALSE) -> Empty
B13: datasheet_3 | C13: datasheet_3 | D13: =IF(B13=C13,"Y","N") -> Y | E13: datasheet 3 | F13: =IF(C13=E13,"Y","N") -> N | H13: 11 | I13: pcb_footprint_cp | J13: =VLOOKUP(I13,'01-Capacitors'!I:J,2,FALSE) -> Empty
B14: datasheet_4 | C14: datasheet_4 | D14: =IF(B14=C14,"Y","N") -> Y | E14: datasheet 4 | F14: =IF(C14=E14,"Y","N") -> N | H14: 12 | I14: pspicetemp | J14: =VLOOKUP(I14,'01-Capacitors'!I:J,2,FALSE) -> Empty
B15: datasheet_5 | C15: datasheet_5 | D15: =IF(B15=C15,"Y","N") -> Y | E15: datasheet 5 | F15: =IF(C15=E15,"Y","N") -> N | H15: 13 | I15: restrictedsubstances | J15: =VLOOKUP(I15,'01-Capacitors'!I:J,2,FALSE) -> Empty
B16: datasheet_6 | C16: datasheet_6 | D16: =IF(B16=C16,"Y","N") -> Y | E16: datasheet 6 | F16: =IF(C16=E16,"Y","N") -> N | H16: 14 | I16: rohs_china | J16: =VLOOKUP(I16,'01-Capacitors'!I:J,2,FALSE) -> Empty
B17: datasheet_7 | C17: datasheet_7 | D17: =IF(B17=C17,"Y","N") -> Y | E17: datasheet 7 | F17: =IF(C17=E17,"Y","N") -> N | H17: 15 | I17: series | J17: =VLOOKUP(I17,'01-Capacitors'!I:J,2,FALSE) -> Empty
B18: deliverytime | C18: deliverytime | D18: =IF(B18=C18,"Y","N") -> Y | E18: deliverytime | F18: =IF(C18=E18,"Y","N") -> Y | H18: 16 | I18: signalmodel | J18: =VLOOKUP(I18,'01-Capacitors'!I:J,2,FALSE) -> Empty
B19: detaildrawing | C19: detaildrawing | D19: =IF(B19=C19,"Y","N") -> Y | E19: detaildrawing | F19: =IF(C19=E19,"Y","N") -> Y | H19: 17 | I19: solderduration_reflow | J19: =VLOOKUP(I19,'01-Capacitors'!I:J,2,FALSE) -> Empty
B20: docversion | C20: docversion | D20: =IF(B20=C20,"Y","N") -> Y | E20: docversion | F20: =IF(C20=E20,"Y","N") -> Y | H20: 18 | I20: solderduration_wave | J20: =VLOOKUP(I20,'01-Capacitors'!I:J,2,FALSE) -> Empty
B21: editor | C21: editor | D21: =IF(B21=C21,"Y","N") -> Y | E21: editor | F21: =IF(C21=E21,"Y","N") -> Y | H21: 19 | I21: soldertemperatur_reflow | J21: =VLOOKUP(I21,'01-Capacitors'!I:J,2,FALSE) -> Empty
B22: free_comment | C22: free_comment | D22: =IF(B22=C22,"Y","N") -> Y | E22: free_comment | F22: =IF(C22=E22,"Y","N") -> Y | H22: 20 | I22: soldertemperatur_wave | J22: =VLOOKUP(I22,'01-Capacitors'!I:J,2,FALSE) -> Empty
... B24: ic_id | C24: ic_id | D24: =IF(B24=C24,"Y","N") -> Y | E24: ic/id | F24: =IF(C24=E24,"Y","N") -> N | H24: 22 | I24: thetajc | J24: =VLOOKUP(I24,'01-Capacitors'!I:J,2,FALSE) -> Empty
B25: id | C25: id | D25: =IF(B25=C25,"Y","N") -> Y | F25: =IF(C25=E25,"Y","N") -> N | G25: Should use "id" for new Table
B26: implementation | C26: implementation | D26: =IF(B26=C26,"Y","N") -> Y | E26: implementation | F26: =IF(C26=E26,"Y","N") -> Y
B27: in_approved_devices | C27: in_approved_devices | D27: =IF(B27=C27,"Y","N") -> Y | E27: in approved devices | F27: =IF(C27=E27,"Y","N") -> N
B28: manufact_1 | C28: manufact_1 | D28: =IF(B28=C28,"Y","N") -> Y | E28: manufact 1 | F28: =IF(C28=E28,"Y","N") -> N
B29: manufact_2 | C29: manufact_2 | D29: =IF(B29=C29,"Y","N") -> Y | E29: manufact 2 | F29: =IF(C29=E29,"Y","N") -> N
B30: manufact_3 | C30: manufact_3 | D30: =IF(B30=C30,"Y","N") -> Y | E30: manufact 3 | F30: =IF(C30=E30,"Y","N") -> N
B31: manufact_4 | C31: manufact_4 | D31: =IF(B31=C31,"Y","N") -> Y | E31: manufact 4 | F31: =IF(C31=E31,"Y","N") -> N
B32: manufact_5 | C32: manufact_5 | D32: =IF(B32=C32,"Y","N") -> Y | E32: manufact 5 | F32: =IF(C32=E32,"Y","N") -> N
B33: manufact_6 | C33: manufact_6 | D33: =IF(B33=C33,"Y","N") -> Y | E33: manufact 6 | F33: =IF(C33=E33,"Y","N") -> N
B34: manufact_7 | C34: manufact_7 | D34: =IF(B34=C34,"Y","N") -> Y | E34: manufact 7 | F34: =IF(C34=E34,"Y","N") -> N
B35: manufact_partnum_1 | C35: manufact_partnum_1 | D35: =IF(B35=C35,"Y","N") -> Y | E35: manufact partnum 1 | F35: =IF(C35=E35,"Y","N") -> N
B36: manufact_partnum_2 | C36: manufact_partnum_2 | D36: =IF(B36=C36,"Y","N") -> Y | E36: manufact partnum 2 | F36: =IF(C36=E36,"Y","N") -> N
B37: manufact_partnum_3 | C37: manufact_partnum_3 | D37: =IF(B37=C37,"Y","N") -> Y | E37: manufact partnum 3 | F37: =IF(C37=E37,"Y","N") -> N
... B70: value_1 | C70: value_1 | D70: =IF(B70=C70,"Y","N") -> Y | E70: value | F70: =IF(C70=E70,"Y","N") -> N
B71: vceo_vds_vgt | C71: vceo_vds_vgt | D71: =IF(B71=C71,"Y","N") -> Y | E71: vceo/vds/vgt | F71: =IF(C71=E71,"Y","N") -> N | G71: should use PostgreDB filed name

Sheet 05-Diodes
A1: DB Name | B1: TABLES_SAPMaxDB | C1: TABLES_PostgreSQLDB | E1: TABLES_AccessDB
A2: Table Name | B2: DIODES | C2: diodes_l2u | D2: B=C? | E2: [05-Diodes] | F2: C=E? | H2: No | I2: AccessDB left | J2: Comment
A3: Field List | B3: ad_alt_footprint | C3: ad_alt_footprint | D3: =IF(B3=C3,"Y","N") -> Y | E3: ad_alt_footprint | F3: =IF(C3=E3,"Y","N") -> Y | H3: 1 | I3: activepartsid | J3: =VLOOKUP(I3,'01-Capacitors'!I:J,2,FALSE) -> Empty
B4: ad_footprint | C4: ad_footprint | D4: =IF(B4=C4,"Y","N") -> Y | E4: ad_footprint | F4: =IF(C4=E4,"Y","N") -> Y | H4: 2 | I4: alt_symbols_cp | J4: =VLOOKUP(I4,'01-Capacitors'!I:J,2,FALSE) -> Empty
B5: ad_symbol | C5: ad_symbol | D5: =IF(B5=C5,"Y","N") -> Y | E5: ad_symbol | F5: =IF(C5=E5,"Y","N") -> Y | H5: 3 | I5: bqr_partnum_mil | J5: =VLOOKUP(I5,'01-Capacitors'!I:J,2,FALSE) -> Empty
B6: alt_symbols | C6: alt_symbols | D6: =IF(B6=C6,"Y","N") -> Y | E6: alt_symbols | F6: =IF(C6=E6,"Y","N") -> Y | H6: 4 | I6: bqr_partnum_sie | J6: =VLOOKUP(I6,'01-Capacitors'!I:J,2,FALSE) -> Empty
B7: annualconsumption | C7: annualconsumption | D7: =IF(B7=C7,"Y","N") -> Y | E7: annualconsumption | F7: =IF(C7=E7,"Y","N") -> Y | H7: 5 | I7: class | J7: =VLOOKUP(I7,'01-Capacitors'!I:J,2,FALSE) -> some with "DISCRETE" value
B8: approvals_of_part | C8: approvals_of_part | D8: =IF(B8=C8,"Y","N") -> Y | E8: approvals of part | F8: =IF(C8=E8,"Y","N") -> N | H8: 6 | I8: compmaterial | J8: =VLOOKUP(I8,'01-Capacitors'!I:J,2,FALSE) -> Empty
B9: approvals_required | C9: approvals_required | D9: =IF(B9=C9,"Y","N") -> Y | E9: approvals required | F9: =IF(C9=E9,"Y","N") -> N | H9: 7 | I9: comptype | J9: =VLOOKUP(I9,'01-Capacitors'!I:J,2,FALSE) -> Empty
B10: datasheet_1 | C10: datasheet_1 | D10: =IF(B10=C10,"Y","N") -> Y | E10: datasheet 1 | F10: =IF(C10=E10,"Y","N") -> N | H10: 8 | I10: further_information | J10: =VLOOKUP(I10,'01-Capacitors'!I:J,2,FALSE) -> Empty
B11: datasheet_2 | C11: datasheet_2 | D11: =IF(B11=C11,"Y","N") -> Y | E11: datasheet 2 | F11: =IF(C11=E11,"Y","N") -> N | H11: 9 | I11: mechmodell | J11: =VLOOKUP(I11,'01-Capacitors'!I:J,2,FALSE) -> Empty
B12: datasheet_3 | C12: datasheet_3 | D12: =IF(B12=C12,"Y","N") -> Y | E12: datasheet 3 | F12: =IF(C12=E12,"Y","N") -> N | H12: 10 | I12: parthistory | J12: =VLOOKUP(I12,'01-Capacitors'!I:J,2,FALSE) -> Empty
B13: datasheet_4 | C13: datasheet_4 | D13: =IF(B13=C13,"Y","N") -> Y | E13: datasheet 4 | F13: =IF(C13=E13,"Y","N") -> N | H13: 11 | I13: pcb_footprint_cp | J13: =VLOOKUP(I13,'01-Capacitors'!I:J,2,FALSE) -> Empty
B14: datasheet_5 | C14: datasheet_5 | D14: =IF(B14=C14,"Y","N") -> Y | E14: datasheet 5 | F14: =IF(C14=E14,"Y","N") -> N | H14: 12 | I14: pspicetemp | J14: =VLOOKUP(I14,'01-Capacitors'!I:J,2,FALSE) -> Empty
B15: datasheet_6 | C15: datasheet_6 | D15: =IF(B15=C15,"Y","N") -> Y | E15: datasheet 6 | F15: =IF(C15=E15,"Y","N") -> N | H15: 13 | I15: restrictedsubstances | J15: =VLOOKUP(I15,'01-Capacitors'!I:J,2,FALSE) -> Empty
... B22: height | C22: height | D22: =IF(B22=C22,"Y","N") -> Y | E22: height | F22: =IF(C22=E22,"Y","N") -> Y | H22: 20 | I22: soldertemperatur_wave | J22: =VLOOKUP(I22,'01-Capacitors'!I:J,2,FALSE) -> Empty
B23: id | C23: id | D23: =IF(B23=C23,"Y","N") -> Y | F23: =IF(C23=E23,"Y","N") -> N | G23: Should use "id" for new Table | H23: 21 | I23: thetajb | J23: =VLOOKUP(I23,'01-Capacitors'!I:J,2,FALSE) -> Empty
B24: if_1 | C24: if_1 | D24: =IF(B24=C24,"Y","N") -> Y | E24: if | F24: =IF(C24=E24,"Y","N") -> N | H24: 22 | I24: thetajc | J24: =VLOOKUP(I24,'01-Capacitors'!I:J,2,FALSE) -> Empty
B25: implementation | C25: implementation | D25: =IF(B25=C25,"Y","N") -> Y | E25: implementation | F25: =IF(C25=E25,"Y","N") -> Y
B26: in_approved_devices | C26: in_approved_devices | D26: =IF(B26=C26,"Y","N") -> Y | E26: in approved devices | F26: =IF(C26=E26,"Y","N") -> N
B27: manufact_1 | C27: manufact_1 | D27: =IF(B27=C27,"Y","N") -> Y | E27: manufact 1 | F27: =IF(C27=E27,"Y","N") -> N
B28: manufact_2 | C28: manufact_2 | D28: =IF(B28=C28,"Y","N") -> Y | E28: manufact 2 | F28: =IF(C28=E28,"Y","N") -> N
B29: manufact_3 | C29: manufact_3 | D29: =IF(B29=C29,"Y","N") -> Y | E29: manufact 3 | F29: =IF(C29=E29,"Y","N") -> N
B30: manufact_4 | C30: manufact_4 | D30: =IF(B30=C30,"Y","N") -> Y | E30: manufact 4 | F30: =IF(C30=E30,"Y","N") -> N
B31: manufact_5 | C31: manufact_5 | D31: =IF(B31=C31,"Y","N") -> Y | E31: manufact 5 | F31: =IF(C31=E31,"Y","N") -> N
B32: manufact_6 | C32: manufact_6 | D32: =IF(B32=C32,"Y","N") -> Y | E32: manufact 6 | F32: =IF(C32=E32,"Y","N") -> N
B33: manufact_7 | C33: manufact_7 | D33: =IF(B33=C33,"Y","N") -> Y | E33: manufact 7 | F33: =IF(C33=E33,"Y","N") -> N
B34: manufact_partnum_1 | C34: manufact_partnum_1 | D34: =IF(B34=C34,"Y","N") -> Y | E34: manufact partnum 1 | F34: =IF(C34=E34,"Y","N") -> N
B35: manufact_partnum_2 | C35: manufact_partnum_2 | D35: =IF(B35=C35,"Y","N") -> Y | E35: manufact partnum 2 | F35: =IF(C35=E35,"Y","N") -> N
B36: manufact_partnum_3 | C36: manufact_partnum_3 | D36: =IF(B36=C36,"Y","N") -> Y | E36: manufact partnum 3 | F36: =IF(C36=E36,"Y","N") -> N
... B71: vrev | C71: vrev | D71: =IF(B71=C71,"Y","N") -> Y | E71: vrev | F71: =IF(C71=E71,"Y","N") -> Y

Sheet 06-ICs_digital
A1: DB Name | B1: TABLES_SAPMaxDB | C1: TABLES_PostgreSQLDB | E1: TABLES_AccessDB
A2: Table Name | B2: ICS_DIGITAL | C2: ics_digital_l2u | D2: B=C? | E2: [06-ICs_digital] | F2: C=E? | H2: No | I2: AccessDB left | J2: Comment
A3: Field List | B3: ad_alt_footprint | C3: ad_alt_footprint | D3: =IF(B3=C3,"Y","N") -> Y | E3: ad_alt_footprint | F3: =IF(C3=E3,"Y","N") -> Y | H3: 1 | I3: activepartsid | J3: =VLOOKUP(I3,'01-Capacitors'!I:J,2,FALSE) -> Empty
B4: ad_footprint | C4: ad_footprint | D4: =IF(B4=C4,"Y","N") -> Y | E4: ad_footprint | F4: =IF(C4=E4,"Y","N") -> Y | H4: 2 | I4: alt_symbols_cp | J4: =VLOOKUP(I4,'01-Capacitors'!I:J,2,FALSE) -> Empty
B5: ad_symbol | C5: ad_symbol | D5: =IF(B5=C5,"Y","N") -> Y | E5: ad_symbol | F5: =IF(C5=E5,"Y","N") -> Y | H5: 3 | I5: bqr_partnum_mil | J5: =VLOOKUP(I5,'01-Capacitors'!I:J,2,FALSE) -> Empty
B6: alt_symbols | C6: alt_symbols | D6: =IF(B6=C6,"Y","N") -> Y | E6: alt_symbols | F6: =IF(C6=E6,"Y","N") -> Y | H6: 4 | I6: bqr_partnum_sie | J6: =VLOOKUP(I6,'01-Capacitors'!I:J,2,FALSE) -> Empty
B7: annualconsumption | C7: annualconsumption | D7: =IF(B7=C7,"Y","N") -> Y | E7: annualconsumption | F7: =IF(C7=E7,"Y","N") -> Y | H7: 5 | I7: class | J7: =VLOOKUP(I7,'01-Capacitors'!I:J,2,FALSE) -> some with "DISCRETE" value
B8: approvals_of_part | C8: approvals_of_part | D8: =IF(B8=C8,"Y","N") -> Y | E8: approvals of part | F8: =IF(C8=E8,"Y","N") -> N | H8: 6 | I8: compmaterial | J8: =VLOOKUP(I8,'01-Capacitors'!I:J,2,FALSE) -> Empty
B9: approvals_required | C9: approvals_required | D9: =IF(B9=C9,"Y","N") -> Y | E9: approvals required | F9: =IF(C9=E9,"Y","N") -> N | H9: 7 | I9: comptype | J9: =VLOOKUP(I9,'01-Capacitors'!I:J,2,FALSE) -> Empty
B10: datasheet_1 | C10: datasheet_1 | D10: =IF(B10=C10,"Y","N") -> Y | E10: datasheet 1 | F10: =IF(C10=E10,"Y","N") -> N | H10: 8 | I10: further_information | J10: =VLOOKUP(I10,'01-Capacitors'!I:J,2,FALSE) -> Empty
B11: datasheet_2 | C11: datasheet_2 | D11: =IF(B11=C11,"Y","N") -> Y | E11: datasheet 2 | F11: =IF(C11=E11,"Y","N") -> N | H11: 9 | I11: mechmodell | J11: =VLOOKUP(I11,'01-Capacitors'!I:J,2,FALSE) -> Empty
B12: datasheet_3 | C12: datasheet_3 | D12: =IF(B12=C12,"Y","N") -> Y | E12: datasheet 3 | F12: =IF(C12=E12,"Y","N") -> N | H12: 10 | I12: parthistory | J12: =VLOOKUP(I12,'01-Capacitors'!I:J,2,FALSE) -> Empty
B13: datasheet_4 | C13: datasheet_4 | D13: =IF(B13=C13,"Y","N") -> Y | E13: datasheet 4 | F13: =IF(C13=E13,"Y","N") -> N | H13: 11 | I13: pcb_footprint_cp | J13: =VLOOKUP(I13,'01-Capacitors'!I:J,2,FALSE) -> Empty
B14: datasheet_5 | C14: datasheet_5 | D14: =IF(B14=C14,"Y","N") -> Y | E14: datasheet 5 | F14: =IF(C14=E14,"Y","N") -> N | H14: 12 | I14: pspicetemp | J14: =VLOOKUP(I14,'01-Capacitors'!I:J,2,FALSE) -> Empty
B15: datasheet_6 | C15: datasheet_6 | D15: =IF(B15=C15,"Y","N") -> Y | E15: datasheet 6 | F15: =IF(C15=E15,"Y","N") -> N | H15: 13 | I15: restrictedsubstances | J15: =VLOOKUP(I15,'01-Capacitors'!I:J,2,FALSE) -> Empty
... B22: height | C22: height | D22: =IF(B22=C22,"Y","N") -> Y | E22: height | F22: =IF(C22=E22,"Y","N") -> Y | H22: 20 | I22: soldertemperatur_wave | J22: =VLOOKUP(I22,'01-Capacitors'!I:J,2,FALSE) -> Empty
B23: id | C23: id | D23: =IF(B23=C23,"Y","N") -> Y | F23: =IF(C23=E23,"Y","N") -> N | G23: Should use "id" for new Table | H23: 21 | I23: thetajb | J23: =VLOOKUP(I23,'01-Capacitors'!I:J,2,FALSE) -> Empty
B24: implementation | C24: implementation | D24: =IF(B24=C24,"Y","N") -> Y | E24: implementation | F24: =IF(C24=E24,"Y","N") -> Y | H24: 22 | I24: thetajc | J24: =VLOOKUP(I24,'01-Capacitors'!I:J,2,FALSE) -> Empty
B25: in_approved_devices | C25: in_approved_devices | D25: =IF(B25=C25,"Y","N") -> Y | E25: in approved devices | F25: =IF(C25=E25,"Y","N") -> N
B26: manufact_1 | C26: manufact_1 | D26: =IF(B26=C26,"Y","N") -> Y | E26: manufact 1 | F26: =IF(C26=E26,"Y","N") -> N
B27: manufact_2 | C27: manufact_2 | D27: =IF(B27=C27,"Y","N") -> Y | E27: manufact 2 | F27: =IF(C27=E27,"Y","N") -> N
B28: manufact_3 | C28: manufact_3 | D28: =IF(B28=C28,"Y","N") -> Y | E28: manufact 3 | F28: =IF(C28=E28,"Y","N") -> N
B29: manufact_4 | C29: manufact_4 | D29: =IF(B29=C29,"Y","N") -> Y | E29: manufact 4 | F29: =IF(C29=E29,"Y","N") -> N
B30: manufact_5 | C30: manufact_5 | D30: =IF(B30=C30,"Y","N") -> Y | E30: manufact 5 | F30: =IF(C30=E30,"Y","N") -> N
B31: manufact_6 | C31: manufact_6 | D31: =IF(B31=C31,"Y","N") -> Y | E31: manufact 6 | F31: =IF(C31=E31,"Y","N") -> N
B32: manufact_7 | C32: manufact_7 | D32: =IF(B32=C32,"Y","N") -> Y | E32: manufact 7 | F32: =IF(C32=E32,"Y","N") -> N
B33: manufact_partnum_1 | C33: manufact_partnum_1 | D33: =IF(B33=C33,"Y","N") -> Y | E33: manufact partnum 1 | F33: =IF(C33=E33,"Y","N") -> N
B34: manufact_partnum_2 | C34: manufact_partnum_2 | D34: =IF(B34=C34,"Y","N") -> Y | E34: manufact partnum 2 | F34: =IF(C34=E34,"Y","N") -> N
B35: manufact_partnum_3 | C35: manufact_partnum_3 | D35: =IF(B35=C35,"Y","N") -> Y | E35: manufact partnum 3 | F35: =IF(C35=E35,"Y","N") -> N
B36: manufact_partnum_4 | C36: manufact_partnum_4 | D36: =IF(B36=C36,"Y","N") -> Y | E36: manufact partnum 4 | F36: =IF(C36=E36,"Y","N") -> N
... B68: vcc | C68: vcc | D68: =IF(B68=C68,"Y","N") -> Y | E68: vcc | F68: =IF(C68=E68,"Y","N") -> Y

Sheet 07-Memory
A1: DB Name | B1: TABLES_SAPMaxDB | C1: TABLES_PostgreSQLDB | E1: TABLES_AccessDB
A2: Table Name | B2: MEMORY | C2: memory_l2u | D2: B=C? | E2: [07-Memory] | F2: C=E? | H2: No | I2: AccessDB left | J2: Comment
A3: Field List | B3: accesstime | C3: accesstime | D3: =IF(B3=C3,"Y","N") -> Y | E3: accesstime | F3: =IF(C3=E3,"Y","N") -> Y | H3: 1 | I3: activepartsid | J3: =VLOOKUP(I3,'01-Capacitors'!I:J,2,FALSE) -> Empty
B4: ad_alt_footprint | C4: ad_alt_footprint | D4: =IF(B4=C4,"Y","N") -> Y | E4: ad_alt_footprint | F4: =IF(C4=E4,"Y","N") -> Y | H4: 2 | I4: alt_symbols_cp | J4: =VLOOKUP(I4,'01-Capacitors'!I:J,2,FALSE) -> Empty
B5: ad_footprint | C5: ad_footprint | D5: =IF(B5=C5,"Y","N") -> Y | E5: ad_footprint | F5: =IF(C5=E5,"Y","N") -> Y | H5: 3 | I5: bqr_partnum_mil | J5: =VLOOKUP(I5,'01-Capacitors'!I:J,2,FALSE) -> Empty
B6: ad_symbol | C6: ad_symbol | D6: =IF(B6=C6,"Y","N") -> Y | E6: ad_symbol | F6: =IF(C6=E6,"Y","N") -> Y | H6: 4 | I6: bqr_partnum_sie | J6: =VLOOKUP(I6,'01-Capacitors'!I:J,2,FALSE) -> Empty
B7: alt_symbols | C7: alt_symbols | D7: =IF(B7=C7,"Y","N") -> Y | E7: alt_symbols | F7: =IF(C7=E7,"Y","N") -> Y | H7: 5 | I7: class | J7: =VLOOKUP(I7,'01-Capacitors'!I:J,2,FALSE) -> some with "DISCRETE" value
B8: annualconsumption | C8: annualconsumption | D8: =IF(B8=C8,"Y","N") -> Y | E8: annualconsumption | F8: =IF(C8=E8,"Y","N") -> Y | H8: 6 | I8: compmaterial | J8: =VLOOKUP(I8,'01-Capacitors'!I:J,2,FALSE) -> Empty
B9: approvals_of_part | C9: approvals_of_part | D9: =IF(B9=C9,"Y","N") -> Y | E9: approvals of part | F9: =IF(C9=E9,"Y","N") -> N | H9: 7 | I9: comptype | J9: =VLOOKUP(I9,'01-Capacitors'!I:J,2,FALSE) -> Empty
B10: approvals_required | C10: approvals_required | D10: =IF(B10=C10,"Y","N") -> Y | E10: approvals required | F10: =IF(C10=E10,"Y","N") -> N | H10: 8 | I10: further_information | J10: =VLOOKUP(I10,'01-Capacitors'!I:J,2,FALSE) -> Empty
B11: datasheet_1 | C11: datasheet_1 | D11: =IF(B11=C11,"Y","N") -> Y | E11: datasheet 1 | F11: =IF(C11=E11,"Y","N") -> N | H11: 9 | I11: mechmodell | J11: =VLOOKUP(I11,'01-Capacitors'!I:J,2,FALSE) -> Empty
B12: datasheet_2 | C12: datasheet_2 | D12: =IF(B12=C12,"Y","N") -> Y | E12: datasheet 2 | F12: =IF(C12=E12,"Y","N") -> N | H12: 10 | I12: parthistory | J12: =VLOOKUP(I12,'01-Capacitors'!I:J,2,FALSE) -> Empty
B13: datasheet_3 | C13: datasheet_3 | D13: =IF(B13=C13,"Y","N") -> Y | E13: datasheet 3 | F13: =IF(C13=E13,"Y","N") -> N | H13: 11 | I13: pcb_footprint_cp | J13: =VLOOKUP(I13,'01-Capacitors'!I:J,2,FALSE) -> Empty
B14: datasheet_4 | C14: datasheet_4 | D14: =IF(B14=C14,"Y","N") -> Y | E14: datasheet 4 | F14: =IF(C14=E14,"Y","N") -> N | H14: 12 | I14: pspicetemp | J14: =VLOOKUP(I14,'01-Capacitors'!I:J,2,FALSE) -> Empty
B15: datasheet_5 | C15: datasheet_5 | D15: =IF(B15=C15,"Y","N") -> Y | E15: datasheet 5 | F15: =IF(C15=E15,"Y","N") -> N | H15: 13 | I15: restrictedsubstances | J15: =VLOOKUP(I15,'01-Capacitors'!I:J,2,FALSE) -> Empty
... B23: height | C23: height | D23: =IF(B23=C23,"Y","N") -> Y | E23: height | F23: =IF(C23=E23,"Y","N") -> Y | H23: 21 | I23: thetajb | J23: =VLOOKUP(I23,'01-Capacitors'!I:J,2,FALSE) -> Empty
B24: id | C24: id | D24: =IF(B24=C24,"Y","N") -> Y | F24: =IF(C24=E24,"Y","N") -> N | G24: Should use "id" for new Table | H24: 22 | I24: thetajc | J24: =VLOOKUP(I24,'01-Capacitors'!I:J,2,FALSE) -> Empty
B25: implementation | C25: implementation | D25: =IF(B25=C25,"Y","N") -> Y | E25: implementation | F25: =IF(C25=E25,"Y","N") -> Y
B26: in_approved_devices | C26: in_approved_devices | D26: =IF(B26=C26,"Y","N") -> Y | E26: in approved devices | F26: =IF(C26=E26,"Y","N") -> N
B27: manufact_1 | C27: manufact_1 | D27: =IF(B27=C27,"Y","N") -> Y | E27: manufact 1 | F27: =IF(C27=E27,"Y","N") -> N
B28: manufact_2 | C28: manufact_2 | D28: =IF(B28=C28,"Y","N") -> Y | E28: manufact 2 | F28: =IF(C28=E28,"Y","N") -> N
B29: manufact_3 | C29: manufact_3 | D29: =IF(B29=C29,"Y","N") -> Y | E29: manufact 3 | F29: =IF(C29=E29,"Y","N") -> N
B30: manufact_4 | C30: manufact_4 | D30: =IF(B30=C30,"Y","N") -> Y | E30: manufact 4 | F30: =IF(C30=E30,"Y","N") -> N
B31: manufact_5 | C31: manufact_5 | D31: =IF(B31=C31,"Y","N") -> Y | E31: manufact 5 | F31: =IF(C31=E31,"Y","N") -> N
B32: manufact_6 | C32: manufact_6 | D32: =IF(B32=C32,"Y","N") -> Y | E32: manufact 6 | F32: =IF(C32=E32,"Y","N") -> N
B33: manufact_7 | C33: manufact_7 | D33: =IF(B33=C33,"Y","N") -> Y | E33: manufact 7 | F33: =IF(C33=E33,"Y","N") -> N
B34: manufact_partnum_1 | C34: manufact_partnum_1 | D34: =IF(B34=C34,"Y","N") -> Y | E34: manufact partnum 1 | F34: =IF(C34=E34,"Y","N") -> N
B35: manufact_partnum_2 | C35: manufact_partnum_2 | D35: =IF(B35=C35,"Y","N") -> Y | E35: manufact partnum 2 | F35: =IF(C35=E35,"Y","N") -> N
B36: manufact_partnum_3 | C36: manufact_partnum_3 | D36: =IF(B36=C36,"Y","N") -> Y | E36: manufact partnum 3 | F36: =IF(C36=E36,"Y","N") -> N
... B70: vcc | C70: vcc | D70: =IF(B70=C70,"Y","N") -> Y | E70: vcc | F70: =IF(C70=E70,"Y","N") -> Y

Sheet 08-ICs_analog
A1: DB Name | B1: TABLES_SAPMaxDB | C1: TABLES_PostgreSQLDB | E1: TABLES_AccessDB
A2: Table Name | B2: ICS_ANALOG | C2: ics_analog_l2u | D2: B=C? | E2: [08-ICs_analog] | F2: C=E? | H2: No | I2: AccessDB left | J2: Comment
A3: Field List | B3: ad_alt_footprint | C3: ad_alt_footprint | D3: =IF(B3=C3,"Y","N") -> Y | E3: ad_alt_footprint | F3: =IF(C3=E3,"Y","N") -> Y | H3: 1 | I3: activepartsid | J3: =VLOOKUP(I3,'01-Capacitors'!I:J,2,FALSE) -> Empty
B4: ad_footprint | C4: ad_footprint | D4: =IF(B4=C4,"Y","N") -> Y | E4: ad_footprint | F4: =IF(C4=E4,"Y","N") -> Y | H4: 2 | I4: alt_symbols_cp | J4: =VLOOKUP(I4,'01-Capacitors'!I:J,2,FALSE) -> Empty
B5: ad_symbol | C5: ad_symbol | D5: =IF(B5=C5,"Y","N") -> Y | E5: ad_symbol | F5: =IF(C5=E5,"Y","N") -> Y | H5: 3 | I5: bqr_partnum_mil | J5: =VLOOKUP(I5,'01-Capacitors'!I:J,2,FALSE) -> Empty
B6: alt_symbols | C6: alt_symbols | D6: =IF(B6=C6,"Y","N") -> Y | E6: alt_symbols | F6: =IF(C6=E6,"Y","N") -> Y | H6: 4 | I6: bqr_partnum_sie | J6: =VLOOKUP(I6,'01-Capacitors'!I:J,2,FALSE) -> Empty
B7: annualconsumption | C7: annualconsumption | D7: =IF(B7=C7,"Y","N") -> Y | E7: annualconsumption | F7: =IF(C7=E7,"Y","N") -> Y | H7: 5 | I7: class | J7: =VLOOKUP(I7,'01-Capacitors'!I:J,2,FALSE) -> some with "DISCRETE" value
B8: approvals_of_part | C8: approvals_of_part | D8: =IF(B8=C8,"Y","N") -> Y | E8: approvals of part | F8: =IF(C8=E8,"Y","N") -> N | H8: 6 | I8: compmaterial | J8: =VLOOKUP(I8,'01-Capacitors'!I:J,2,FALSE) -> Empty
B9: approvals_required | C9: approvals_required | D9: =IF(B9=C9,"Y","N") -> Y | E9: approvals required | F9: =IF(C9=E9,"Y","N") -> N | H9: 7 | I9: comptype | J9: =VLOOKUP(I9,'01-Capacitors'!I:J,2,FALSE) -> Empty
B10: datasheet_1 | C10: datasheet_1 | D10: =IF(B10=C10,"Y","N") -> Y | E10: datasheet 1 | F10: =IF(C10=E10,"Y","N") -> N | H10: 8 | I10: further_information | J10: =VLOOKUP(I10,'01-Capacitors'!I:J,2,FALSE) -> Empty
B11: datasheet_2 | C11: datasheet_2 | D11: =IF(B11=C11,"Y","N") -> Y | E11: datasheet 2 | F11: =IF(C11=E11,"Y","N") -> N | H11: 9 | I11: mechmodell | J11: =VLOOKUP(I11,'01-Capacitors'!I:J,2,FALSE) -> Empty
B12: datasheet_3 | C12: datasheet_3 | D12: =IF(B12=C12,"Y","N") -> Y | E12: datasheet 3 | F12: =IF(C12=E12,"Y","N") -> N | H12: 10 | I12: parthistory | J12: =VLOOKUP(I12,'01-Capacitors'!I:J,2,FALSE) -> Empty
B13: datasheet_4 | C13: datasheet_4 | D13: =IF(B13=C13,"Y","N") -> Y | E13: datasheet 4 | F13: =IF(C13=E13,"Y","N") -> N | H13: 11 | I13: pcb_footprint_cp | J13: =VLOOKUP(I13,'01-Capacitors'!I:J,2,FALSE) -> Empty
B14: datasheet_5 | C14: datasheet_5 | D14: =IF(B14=C14,"Y","N") -> Y | E14: datasheet 5 | F14: =IF(C14=E14,"Y","N") -> N | H14: 12 | I14: pspicetemp | J14: =VLOOKUP(I14,'01-Capacitors'!I:J,2,FALSE) -> Empty
B15: datasheet_6 | C15: datasheet_6 | D15: =IF(B15=C15,"Y","N") -> Y | E15: datasheet 6 | F15: =IF(C15=E15,"Y","N") -> N | H15: 13 | I15: restrictedsubstances | J15: =VLOOKUP(I15,'01-Capacitors'!I:J,2,FALSE) -> Empty
... B22: height | C22: height | D22: =IF(B22=C22,"Y","N") -> Y | E22: height | F22: =IF(C22=E22,"Y","N") -> Y | H22: 20 | I22: soldertemperatur_wave | J22: =VLOOKUP(I22,'01-Capacitors'!I:J,2,FALSE) -> Empty
B23: id | C23: id | D23: =IF(B23=C23,"Y","N") -> Y | F23: =IF(C23=E23,"Y","N") -> N | G23: Should use "id" for new Table | H23: 21 | I23: thetajb | J23: =VLOOKUP(I23,'01-Capacitors'!I:J,2,FALSE) -> Empty
B24: implementation | C24: implementation | D24: =IF(B24=C24,"Y","N") -> Y | E24: implementation | F24: =IF(C24=E24,"Y","N") -> Y | H24: 22 | I24: thetajc | J24: =VLOOKUP(I24,'01-Capacitors'!I:J,2,FALSE) -> Empty
B25: in_approved_devices | C25: in_approved_devices | D25: =IF(B25=C25,"Y","N") -> Y | E25: in approved devices | F25: =IF(C25=E25,"Y","N") -> N
B26: manufact_1 | C26: manufact_1 | D26: =IF(B26=C26,"Y","N") -> Y | E26: manufact 1 | F26: =IF(C26=E26,"Y","N") -> N
B27: manufact_2 | C27: manufact_2 | D27: =IF(B27=C27,"Y","N") -> Y | E27: manufact 2 | F27: =IF(C27=E27,"Y","N") -> N
B28: manufact_3 | C28: manufact_3 | D28: =IF(B28=C28,"Y","N") -> Y | E28: manufact 3 | F28: =IF(C28=E28,"Y","N") -> N
B29: manufact_4 | C29: manufact_4 | D29: =IF(B29=C29,"Y","N") -> Y | E29: manufact 4 | F29: =IF(C29=E29,"Y","N") -> N
B30: manufact_5 | C30: manufact_5 | D30: =IF(B30=C30,"Y","N") -> Y | E30: manufact 5 | F30: =IF(C30=E30,"Y","N") -> N
B31: manufact_6 | C31: manufact_6 | D31: =IF(B31=C31,"Y","N") -> Y | E31: manufact 6 | F31: =IF(C31=E31,"Y","N") -> N
B32: manufact_7 | C32: manufact_7 | D32: =IF(B32=C32,"Y","N") -> Y | E32: manufact 7 | F32: =IF(C32=E32,"Y","N") -> N
B33: manufact_partnum_1 | C33: manufact_partnum_1 | D33: =IF(B33=C33,"Y","N") -> Y | E33: manufact partnum 1 | F33: =IF(C33=E33,"Y","N") -> N
B34: manufact_partnum_2 | C34: manufact_partnum_2 | D34: =IF(B34=C34,"Y","N") -> Y | E34: manufact partnum 2 | F34: =IF(C34=E34,"Y","N") -> N
B35: manufact_partnum_3 | C35: manufact_partnum_3 | D35: =IF(B35=C35,"Y","N") -> Y | E35: manufact partnum 3 | F35: =IF(C35=E35,"Y","N") -> N
B36: manufact_partnum_4 | C36: manufact_partnum_4 | D36: =IF(B36=C36,"Y","N") -> Y | E36: manufact partnum 4 | F36: =IF(C36=E36,"Y","N") -> N
... B68: vcc | C68: vcc | D68: =IF(B68=C68,"Y","N") -> Y | E68: vcc | F68: =IF(C68=E68,"Y","N") -> Y

Sheet 09-Regulators
A1: DB Name | B1: TABLES_SAPMaxDB | C1: TABLES_PostgreSQLDB | E1: TABLES_AccessDB
A2: Table Name | B2: REGULATORS | C2: regulators_l2u | D2: B=C? | E2: [09-Regulators] | F2: C=E? | H2: No | I2: AccessDB left | J2: Comment
A3: Field List | B3: ad_alt_footprint | C3: ad_alt_footprint | D3: =IF(B3=C3,"Y","N") -> Y | E3: ad_alt_footprint | F3: =IF(C3=E3,"Y","N") -> Y | H3: 1 | I3: activepartsid | J3: =VLOOKUP(I3,'01-Capacitors'!I:J,2,FALSE) -> Empty
B4: ad_footprint | C4: ad_footprint | D4: =IF(B4=C4,"Y","N") -> Y | E4: ad_footprint | F4: =IF(C4=E4,"Y","N") -> Y | H4: 2 | I4: alt_symbols_cp | J4: =VLOOKUP(I4,'01-Capacitors'!I:J,2,FALSE) -> Empty
B5: ad_symbol | C5: ad_symbol | D5: =IF(B5=C5,"Y","N") -> Y | E5: ad_symbol | F5: =IF(C5=E5,"Y","N") -> Y | H5: 3 | I5: bqr_partnum_mil | J5: =VLOOKUP(I5,'01-Capacitors'!I:J,2,FALSE) -> Empty
B6: alt_symbols | C6: alt_symbols | D6: =IF(B6=C6,"Y","N") -> Y | E6: alt_symbols | F6: =IF(C6=E6,"Y","N") -> Y | H6: 4 | I6: bqr_partnum_sie | J6: =VLOOKUP(I6,'01-Capacitors'!I:J,2,FALSE) -> Empty
B7: annualconsumption | C7: annualconsumption | D7: =IF(B7=C7,"Y","N") -> Y | E7: annualconsumption | F7: =IF(C7=E7,"Y","N") -> Y | H7: 5 | I7: class | J7: =VLOOKUP(I7,'01-Capacitors'!I:J,2,FALSE) -> some with "DISCRETE" value
B8: approvals_of_part | C8: approvals_of_part | D8: =IF(B8=C8,"Y","N") -> Y | E8: approvals of part | F8: =IF(C8=E8,"Y","N") -> N | H8: 6 | I8: compmaterial | J8: =VLOOKUP(I8,'01-Capacitors'!I:J,2,FALSE) -> Empty
B9: approvals_required | C9: approvals_required | D9: =IF(B9=C9,"Y","N") -> Y | E9: approvals required | F9: =IF(C9=E9,"Y","N") -> N | H9: 7 | I9: comptype | J9: =VLOOKUP(I9,'01-Capacitors'!I:J,2,FALSE) -> Empty
B10: datasheet_1 | C10: datasheet_1 | D10: =IF(B10=C10,"Y","N") -> Y | E10: datasheet 1 | F10: =IF(C10=E10,"Y","N") -> N | H10: 8 | I10: further_information | J10: =VLOOKUP(I10,'01-Capacitors'!I:J,2,FALSE) -> Empty
B11: datasheet_2 | C11: datasheet_2 | D11: =IF(B11=C11,"Y","N") -> Y | E11: datasheet 2 | F11: =IF(C11=E11,"Y","N") -> N | H11: 9 | I11: mechmodell | J11: =VLOOKUP(I11,'01-Capacitors'!I:J,2,FALSE) -> Empty
B12: datasheet_3 | C12: datasheet_3 | D12: =IF(B12=C12,"Y","N") -> Y | E12: datasheet 3 | F12: =IF(C12=E12,"Y","N") -> N | H12: 10 | I12: parthistory | J12: =VLOOKUP(I12,'01-Capacitors'!I:J,2,FALSE) -> Empty
B13: datasheet_4 | C13: datasheet_4 | D13: =IF(B13=C13,"Y","N") -> Y | E13: datasheet 4 | F13: =IF(C13=E13,"Y","N") -> N | H13: 11 | I13: pcb_footprint_cp | J13: =VLOOKUP(I13,'01-Capacitors'!I:J,2,FALSE) -> Empty
B14: datasheet_5 | C14: datasheet_5 | D14: =IF(B14=C14,"Y","N") -> Y | E14: datasheet 5 | F14: =IF(C14=E14,"Y","N") -> N | H14: 12 | I14: pspicetemp | J14: =VLOOKUP(I14,'01-Capacitors'!I:J,2,FALSE) -> Empty
B15: datasheet_6 | C15: datasheet_6 | D15: =IF(B15=C15,"Y","N") -> Y | E15: datasheet 6 | F15: =IF(C15=E15,"Y","N") -> N | H15: 13 | I15: restrictedsubstances | J15: =VLOOKUP(I15,'01-Capacitors'!I:J,2,FALSE) -> Empty
... B22: height | C22: height | D22: =IF(B22=C22,"Y","N") -> Y | E22: height | F22: =IF(C22=E22,"Y","N") -> Y | H22: 20 | I22: soldertemperatur_wave | J22: =VLOOKUP(I22,'01-Capacitors'!I:J,2,FALSE) -> Empty
B23: id | C23: id | D23: =IF(B23=C23,"Y","N") -> Y | F23: =IF(C23=E23,"Y","N") -> N | G23: Should use "id" for new Table | H23: 21 | I23: thetajb | J23: =VLOOKUP(I23,'01-Capacitors'!I:J,2,FALSE) -> Empty
B24: implementation | C24: implementation | D24: =IF(B24=C24,"Y","N") -> Y | E24: implementation | F24: =IF(C24=E24,"Y","N") -> Y | H24: 22 | I24: thetajc | J24: =VLOOKUP(I24,'01-Capacitors'!I:J,2,FALSE) -> Empty
B25: in_approved_devices | C25: in_approved_devices | D25: =IF(B25=C25,"Y","N") -> Y | E25: in approved devices | F25: =IF(C25=E25,"Y","N") -> N
B26: manufact_1 | C26: manufact_1 | D26: =IF(B26=C26,"Y","N") -> Y | E26: manufact 1 | F26: =IF(C26=E26,"Y","N") -> N
B27: manufact_2 | C27: manufact_2 | D27: =IF(B27=C27,"Y","N") -> Y | E27: manufact 2 | F27: =IF(C27=E27,"Y","N") -> N
B28: manufact_3 | C28: manufact_3 | D28: =IF(B28=C28,"Y","N") -> Y | E28: manufact 3 | F28: =IF(C28=E28,"Y","N") -> N
B29: manufact_4 | C29: manufact_4 | D29: =IF(B29=C29,"Y","N") -> Y | E29: manufact 4 | F29: =IF(C29=E29,"Y","N") -> N
B30: manufact_5 | C30: manufact_5 | D30: =IF(B30=C30,"Y","N") -> Y | E30: manufact 5 | F30: =IF(C30=E30,"Y","N") -> N
B31: manufact_6 | C31: manufact_6 | D31: =IF(B31=C31,"Y","N") -> Y | E31: manufact 6 | F31: =IF(C31=E31,"Y","N") -> N
B32: manufact_7 | C32: manufact_7 | D32: =IF(B32=C32,"Y","N") -> Y | E32: manufact 7 | F32: =IF(C32=E32,"Y","N") -> N
B33: manufact_partnum_1 | C33: manufact_partnum_1 | D33: =IF(B33=C33,"Y","N") -> Y | E33: manufact partnum 1 | F33: =IF(C33=E33,"Y","N") -> N
B34: manufact_partnum_2 | C34: manufact_partnum_2 | D34: =IF(B34=C34,"Y","N") -> Y | E34: manufact partnum 2 | F34: =IF(C34=E34,"Y","N") -> N
B35: manufact_partnum_3 | C35: manufact_partnum_3 | D35: =IF(B35=C35,"Y","N") -> Y | E35: manufact partnum 3 | F35: =IF(C35=E35,"Y","N") -> N
B36: manufact_partnum_4 | C36: manufact_partnum_4 | D36: =IF(B36=C36,"Y","N") -> Y | E36: manufact partnum 4 | F36: =IF(C36=E36,"Y","N") -> N
... B68: vcc | C68: vcc | D68: =IF(B68=C68,"Y","N") -> Y | E68: vcc | F68: =IF(C68=E68,"Y","N") -> Y

Sheet 10-Converters
A1: DB Name | B1: TABLES_SAPMaxDB | C1: TABLES_PostgreSQLDB | E1: TABLES_AccessDB
A2: Table Name | B2: CONVERTERS | C2: converters_l2u | D2: B=C? | E2: [10-Converters] | F2: C=E? | H2: No | I2: AccessDB left | J2: Comment
A3: Field List | B3: ad_alt_footprint | C3: ad_alt_footprint | D3: =IF(B3=C3,"Y","N") -> Y | E3: ad_alt_footprint | F3: =IF(C3=E3,"Y","N") -> Y | H3: 1 | I3: activepartsid | J3: =VLOOKUP(I3,'01-Capacitors'!I:J,2,FALSE) -> Empty
B4: ad_footprint | C4: ad_footprint | D4: =IF(B4=C4,"Y","N") -> Y | E4: ad_footprint | F4: =IF(C4=E4,"Y","N") -> Y | H4: 2 | I4: alt_symbols_cp | J4: =VLOOKUP(I4,'01-Capacitors'!I:J,2,FALSE) -> Empty
B5: ad_symbol | C5: ad_symbol | D5: =IF(B5=C5,"Y","N") -> Y | E5: ad_symbol | F5: =IF(C5=E5,"Y","N") -> Y | H5: 3 | I5: bqr_partnum_mil | J5: =VLOOKUP(I5,'01-Capacitors'!I:J,2,FALSE) -> Empty
B6: alt_symbols | C6: alt_symbols | D6: =IF(B6=C6,"Y","N") -> Y | E6: alt_symbols | F6: =IF(C6=E6,"Y","N") -> Y | H6: 4 | I6: bqr_partnum_sie | J6: =VLOOKUP(I6,'01-Capacitors'!I:J,2,FALSE) -> Empty
B7: annualconsumption | C7: annualconsumption | D7: =IF(B7=C7,"Y","N") -> Y | E7: annualconsumption | F7: =IF(C7=E7,"Y","N") -> Y | H7: 5 | I7: class | J7: =VLOOKUP(I7,'01-Capacitors'!I:J,2,FALSE) -> some with "DISCRETE" value
B8: approvals_of_part | C8: approvals_of_part | D8: =IF(B8=C8,"Y","N") -> Y | E8: approvals of part | F8: =IF(C8=E8,"Y","N") -> N | H8: 6 | I8: compmaterial | J8: =VLOOKUP(I8,'01-Capacitors'!I:J,2,FALSE) -> Empty
B9: approvals_required | C9: approvals_required | D9: =IF(B9=C9,"Y","N") -> Y | E9: approvals required | F9: =IF(C9=E9,"Y","N") -> N | H9: 7 | I9: comptype | J9: =VLOOKUP(I9,'01-Capacitors'!I:J,2,FALSE) -> Empty
B10: datasheet_1 | C10: datasheet_1 | D10: =IF(B10=C10,"Y","N") -> Y | E10: datasheet 1 | F10: =IF(C10=E10,"Y","N") -> N | H10: 8 | I10: further_information | J10: =VLOOKUP(I10,'01-Capacitors'!I:J,2,FALSE) -> Empty
B11: datasheet_2 | C11: datasheet_2 | D11: =IF(B11=C11,"Y","N") -> Y | E11: datasheet 2 | F11: =IF(C11=E11,"Y","N") -> N | H11: 9 | I11: mechmodell | J11: =VLOOKUP(I11,'01-Capacitors'!I:J,2,FALSE) -> Empty
B12: datasheet_3 | C12: datasheet_3 | D12: =IF(B12=C12,"Y","N") -> Y | E12: datasheet 3 | F12: =IF(C12=E12,"Y","N") -> N | H12: 10 | I12: parthistory | J12: =VLOOKUP(I12,'01-Capacitors'!I:J,2,FALSE) -> Empty
B13: datasheet_4 | C13: datasheet_4 | D13: =IF(B13=C13,"Y","N") -> Y | E13: datasheet 4 | F13: =IF(C13=E13,"Y","N") -> N | H13: 11 | I13: pcb_footprint_cp | J13: =VLOOKUP(I13,'01-Capacitors'!I:J,2,FALSE) -> Empty
B14: datasheet_5 | C14: datasheet_5 | D14: =IF(B14=C14,"Y","N") -> Y | E14: datasheet 5 | F14: =IF(C14=E14,"Y","N") -> N | H14: 12 | I14: pspicetemp | J14: =VLOOKUP(I14,'01-Capacitors'!I:J,2,FALSE) -> Empty
B15: datasheet_6 | C15: datasheet_6 | D15: =IF(B15=C15,"Y","N") -> Y | E15: datasheet 6 | F15: =IF(C15=E15,"Y","N") -> N | H15: 13 | I15: restrictedsubstances | J15: =VLOOKUP(I15,'01-Capacitors'!I:J,2,FALSE) -> Empty
... B22: height | C22: height | D22: =IF(B22=C22,"Y","N") -> Y | E22: height | F22: =IF(C22=E22,"Y","N") -> Y | H22: 20 | I22: soldertemperatur_wave | J22: =VLOOKUP(I22,'01-Capacitors'!I:J,2,FALSE) -> Empty
B23: id | C23: id | D23: =IF(B23=C23,"Y","N") -> Y | F23: =IF(C23=E23,"Y","N") -> N | G23: Should use "id" for new Table | H23: 21 | I23: thetajb | J23: =VLOOKUP(I23,'01-Capacitors'!I:J,2,FALSE) -> Empty
B24: implementation | C24: implementation | D24: =IF(B24=C24,"Y","N") -> Y | E24: implementation | F24: =IF(C24=E24,"Y","N") -> Y | H24: 22 | I24: thetajc | J24: =VLOOKUP(I24,'01-Capacitors'!I:J,2,FALSE) -> Empty
B25: in_approved_devices | C25: in_approved_devices | D25: =IF(B25=C25,"Y","N") -> Y | E25: in approved devices | F25: =IF(C25=E25,"Y","N") -> N
B26: manufact_1 | C26: manufact_1 | D26: =IF(B26=C26,"Y","N") -> Y | E26: manufact 1 | F26: =IF(C26=E26,"Y","N") -> N
B27: manufact_2 | C27: manufact_2 | D27: =IF(B27=C27,"Y","N") -> Y | E27: manufact 2 | F27: =IF(C27=E27,"Y","N") -> N
B28: manufact_3 | C28: manufact_3 | D28: =IF(B28=C28,"Y","N") -> Y | E28: manufact 3 | F28: =IF(C28=E28,"Y","N") -> N
B29: manufact_4 | C29: manufact_4 | D29: =IF(B29=C29,"Y","N") -> Y | E29: manufact 4 | F29: =IF(C29=E29,"Y","N") -> N
B30: manufact_5 | C30: manufact_5 | D30: =IF(B30=C30,"Y","N") -> Y | E30: manufact 5 | F30: =IF(C30=E30,"Y","N") -> N
B31: manufact_6 | C31: manufact_6 | D31: =IF(B31=C31,"Y","N") -> Y | E31: manufact 6 | F31: =IF(C31=E31,"Y","N") -> N
B32: manufact_7 | C32: manufact_7 | D32: =IF(B32=C32,"Y","N") -> Y | E32: manufact 7 | F32: =IF(C32=E32,"Y","N") -> N
B33: manufact_partnum_1 | C33: manufact_partnum_1 | D33: =IF(B33=C33,"Y","N") -> Y | E33: manufact partnum 1 | F33: =IF(C33=E33,"Y","N") -> N
B34: manufact_partnum_2 | C34: manufact_partnum_2 | D34: =IF(B34=C34,"Y","N") -> Y | E34: manufact partnum 2 | F34: =IF(C34=E34,"Y","N") -> N
B35: manufact_partnum_3 | C35: manufact_partnum_3 | D35: =IF(B35=C35,"Y","N") -> Y | E35: manufact partnum 3 | F35: =IF(C35=E35,"Y","N") -> N
B36: manufact_partnum_4 | C36: manufact_partnum_4 | D36: =IF(B36=C36,"Y","N") -> Y | E36: manufact partnum 4 | F36: =IF(C36=E36,"Y","N") -> N
... B68: vcc | C68: vcc | D68: =IF(B68=C68,"Y","N") -> Y | E68: vcc | F68: =IF(C68=E68,"Y","N") -> Y

Sheet 11-OP_Amps
A1: DB Name | B1: TABLES_SAPMaxDB | C1: TABLES_PostgreSQLDB | E1: TABLES_AccessDB
A2: Table Name | B2: OP_AMPS | C2: op_amps_l2u | D2: B=C? | E2: [11-OP_Amps] | F2: C=E? | H2: No | I2: AccessDB left | J2: Comment
A3: Field List | B3: ad_alt_footprint | C3: ad_alt_footprint | D3: =IF(B3=C3,"Y","N") -> Y | E3: ad_alt_footprint | F3: =IF(C3=E3,"Y","N") -> Y | H3: 1 | I3: activepartsid | J3: =VLOOKUP(I3,'01-Capacitors'!I:J,2,FALSE) -> Empty
B4: ad_footprint | C4: ad_footprint | D4: =IF(B4=C4,"Y","N") -> Y | E4: ad_footprint | F4: =IF(C4=E4,"Y","N") -> Y | H4: 2 | I4: alt_symbols_cp | J4: =VLOOKUP(I4,'01-Capacitors'!I:J,2,FALSE) -> Empty
B5: ad_symbol | C5: ad_symbol | D5: =IF(B5=C5,"Y","N") -> Y | E5: ad_symbol | F5: =IF(C5=E5,"Y","N") -> Y | H5: 3 | I5: bqr_partnum_mil | J5: =VLOOKUP(I5,'01-Capacitors'!I:J,2,FALSE) -> Empty
B6: alt_symbols | C6: alt_symbols | D6: =IF(B6=C6,"Y","N") -> Y | E6: alt_symbols | F6: =IF(C6=E6,"Y","N") -> Y | H6: 4 | I6: bqr_partnum_sie | J6: =VLOOKUP(I6,'01-Capacitors'!I:J,2,FALSE) -> Empty
B7: annualconsumption | C7: annualconsumption | D7: =IF(B7=C7,"Y","N") -> Y | E7: annualconsumption | F7: =IF(C7=E7,"Y","N") -> Y | H7: 5 | I7: class | J7: =VLOOKUP(I7,'01-Capacitors'!I:J,2,FALSE) -> some with "DISCRETE" value
B8: approvals_of_part | C8: approvals_of_part | D8: =IF(B8=C8,"Y","N") -> Y | E8: approvals of part | F8: =IF(C8=E8,"Y","N") -> N | H8: 6 | I8: compmaterial | J8: =VLOOKUP(I8,'01-Capacitors'!I:J,2,FALSE) -> Empty
B9: approvals_required | C9: approvals_required | D9: =IF(B9=C9,"Y","N") -> Y | E9: approvals required | F9: =IF(C9=E9,"Y","N") -> N | H9: 7 | I9: comptype | J9: =VLOOKUP(I9,'01-Capacitors'!I:J,2,FALSE) -> Empty
B10: datasheet_1 | C10: datasheet_1 | D10: =IF(B10=C10,"Y","N") -> Y | E10: datasheet 1 | F10: =IF(C10=E10,"Y","N") -> N | H10: 8 | I10: further_information | J10: =VLOOKUP(I10,'01-Capacitors'!I:J,2,FALSE) -> Empty
B11: datasheet_2 | C11: datasheet_2 | D11: =IF(B11=C11,"Y","N") -> Y | E11: datasheet 2 | F11: =IF(C11=E11,"Y","N") -> N | H11: 9 | I11: mechmodell | J11: =VLOOKUP(I11,'01-Capacitors'!I:J,2,FALSE) -> Empty
B12: datasheet_3 | C12: datasheet_3 | D12: =IF(B12=C12,"Y","N") -> Y | E12: datasheet 3 | F12: =IF(C12=E12,"Y","N") -> N | H12: 10 | I12: parthistory | J12: =VLOOKUP(I12,'01-Capacitors'!I:J,2,FALSE) -> Empty
B13: datasheet_4 | C13: datasheet_4 | D13: =IF(B13=C13,"Y","N") -> Y | E13: datasheet 4 | F13: =IF(C13=E13,"Y","N") -> N | H13: 11 | I13: pcb_footprint_cp | J13: =VLOOKUP(I13,'01-Capacitors'!I:J,2,FALSE) -> Empty
B14: datasheet_5 | C14: datasheet_5 | D14: =IF(B14=C14,"Y","N") -> Y | E14: datasheet 5 | F14: =IF(C14=E14,"Y","N") -> N | H14: 12 | I14: pspicetemp | J14: =VLOOKUP(I14,'01-Capacitors'!I:J,2,FALSE) -> Empty
B15: datasheet_6 | C15: datasheet_6 | D15: =IF(B15=C15,"Y","N") -> Y | E15: datasheet 6 | F15: =IF(C15=E15,"Y","N") -> N | H15: 13 | I15: restrictedsubstances | J15: =VLOOKUP(I15,'01-Capacitors'!I:J,2,FALSE) -> Empty
... B22: height | C22: height | D22: =IF(B22=C22,"Y","N") -> Y | E22: height | F22: =IF(C22=E22,"Y","N") -> Y | H22: 20 | I22: soldertemperatur_wave | J22: =VLOOKUP(I22,'01-Capacitors'!I:J,2,FALSE) -> Empty
B23: icc | C23: icc | D23: =IF(B23=C23,"Y","N") -> Y | E23: icc | F23: =IF(C23=E23,"Y","N") -> Y | G23: Should use "id" for new Table | H23: 21 | I23: thetajb | J23: =VLOOKUP(I23,'01-Capacitors'!I:J,2,FALSE) -> Empty
